Workbook

Sheet Guide
B2: OUTIL D'ANALYSE ET DE RAPPORTAGE PDM — MEDAIR
B3: Guide d'utilisation rapide / Quick User Guide
B5: 1. Structure du classeur
B6: • Config : langue (FR/EN), listes de référence, seuils.
B7: • Raw_Data : collez ici l'export brut de votre Google Sheets (Kobo → n8n → Sheets). Ne touchez pas aux en-têtes (ligne 1).
B8: • Data_Clean : nettoyage et normalisation automatique (formules) — ne pas modifier.
B9: • QC_Qualite : détection automatique des doublons, valeurs manquantes, incohérences.
B10: • Indicateurs : tous les indicateurs clés calculés automatiquement, avec filtres (zone, secteur, sexe, période).
B11: • Desagregation : répartitions par sexe, âge, zone, secteur.
B12: • Dashboard : tableau de bord visuel avec graphiques dynamiques et filtres.
B13: • Rapport : résumé exécutif et tableau de synthèse générés automatiquement, prêt à exporter en PDF.
B15: 2. Mise à jour des données
... B35: • Noir : formule (ne pas modifier).

Sheet Config
A1: PARAMETRES / CONFIG
A3: Langue du tableau de bord | B3: FR
A5: Seuil satisfaction jugee 'bonne' (score /5) | B5: 4
A6: Nombre max de lignes de donnees (Raw_Data) | B6: 1000
A9: Listes de reference (modifiable si nouvelle enquete)
A10: Zones | B10: Secteurs | D10: Sexe | E10: Reponses oui/non
A11: Tous | B11: Tous | D11: Tous | E11: oui
A12: zone_1 | B12: wash | D12: feminin | E12: non
A13: zone_2 | B13: sante | D13: masculin
A14: zone_3 | B14: nutrition
A15: zone_4 | B15: shelter
B16: drr

Sheet Raw_Data
A1: id | B1: today | C1: start | D1: end | E1: nom_enqueteur | F1: zone | G1: secteur | H1: localite | I1: code_menage | J1: sexe | K1: age | L1: statut_repondant | M1: vulnerabilite | N1: q_qualite_globale | O1: q_delai_distribution | P1: q_adequation_besoins | Q1: q_usage_prevu | R1: q_raison_non_utilisation | S1: satisfaction_globale | T1: q_satisfaction_personnel | U1: q_recommandation | V1: q_info_disponible | W1: date_enquete | X1: qc_missing_fields | Y1: qc_duplicate | Z1: qc_has_issue | AA1: satisfaction_score | AB1: bien_utilise_bool | AC1: mecanisme_connu_bool | AD1: processed_at | AE1: uuid | AF1: deviceid | AG1: sexe_repondant | AH1: age_repondant | AI1: vulnerabilite_menage | AJ1: type_assistance_recue | AK1: q_utilisation_bien | AL1: q_connaissance_mecanisme | AM1: q_utilisation_mecanisme | AN1: q_satisfaction_reponse | AO1: q_acces_equitable | AP1: q_securite_distribution | AQ1: q_priorite_vulnerables | AR1: q_dignite_traitement | AS1: q_suggestion | AT1: q_commentaire_libre | AU1: submitted_by | AV1: submission_time
A2: 841833601 | B2: 46251 | C2: 46251.603 | D2: 46251.605 | E2: Guruu | F2: zone_1 | G2: shelter | H2: Hffnd | I2: 3553 | J2: feminin | K2: 52 | L2: epoux_epouse | M2: handicap | N2: neutre | O2: neutre | P2: non | Q2: non | R2: Jef | S2: tres_insatisfait | T2: insatisfait | U2: non | V2: oui | W2: 46251.606 | X2: [] | Y2: FALSE | Z2: FALSE | AA2: 1 | AD2: 46248 | AE2: c4e3d6e4936d4ba5a5dbe6b964e7be20 | AF2: collect:HuAzha14QZ6E9osM | AG2: feminin | AH2: 52 | AI2: handicap | AJ2: kit_wash | AK2: non | AL2: non | AM2: oui | AN2: neutre | AO2: non | AP2: oui | AQ2: non | AR2: non | AS2: C it gyf | AT2: Fjeyf | AU2: dirianatins | AV2: 46251.48
A3: 844730793 | B3: 46251 | C3: 46254.237 | D3: 46254.237 | E3: Guruu | F3: zone_1 | G3: shelter | H3: Hffnd | I3: 3553 | J3: feminin | K3: 52 | L3: epoux_epouse | M3: handicap | N3: neutre | O3: neutre | P3: non | Q3: non | R3: Jef | S3: tres_insatisfait | T3: insatisfait | U3: non | V3: oui | W3: 46254.363 | X3: [] | Y3: FALSE | Z3: FALSE | AA3: 1 | AD3: 46248 | AE3: c4e3d6e4936d4ba5a5dbe6b964e7be20 | AF3: collect:HuAzha14QZ6E9osM | AG3: feminin | AH3: 52 | AI3: handicap | AJ3: kit_wash | AK3: non | AL3: non | AM3: oui | AN3: neutre | AO3: non | AP3: oui | AQ3: non | AR3: non | AS3: C it gyf | AT3: Fjeyf | AU3: dirianatins | AV3: 46254.237
A4: 844911848 | B4: 46251 | C4: 46254.371 | D4: 46254.371 | E4: Guruu | F4: zone_1 | G4: shelter | H4: Hffnd | I4: 3553 | J4: feminin | K4: 52 | L4: epoux_epouse | M4: handicap | N4: neutre | O4: neutre | P4: non | Q4: non | R4: Jef | S4: tres_insatisfait | T4: insatisfait | U4: non | V4: oui | W4: 46254.496 | X4: [] | Y4: FALSE | Z4: FALSE | AA4: 1 | AD4: 46248 | AE4: c4e3d6e4936d4ba5a5dbe6b964e7be20 | AF4: collect:HuAzha14QZ6E9osM | AG4: feminin | AH4: 52 | AI4: handicap | AJ4: kit_wash | AK4: non | AL4: non | AM4: oui | AN4: neutre | AO4: non | AP4: oui | AQ4: non | AR4: non | AS4: C it gyf | AT4: Fjeyf | AU4: dirianatins | AV4: 46254.371
A5: 844927787 | B5: 46254 | C5: 46254.463 | D5: 46254.464 | E5: fetra | F5: zone_3 | G5: sante | H5: tena kidy | J5: feminin | K5: 44 | L5: epoux_epouse | M5: femme_enceinte_allaitante menage_monoparental | N5: insatisfait | O5: satisfait | P5: oui | Q5: oui | R5: aucune | S5: neutre | T5: satisfait | U5: non | V5: oui | W5: 46254.507 | X5: [] | Y5: FALSE | Z5: FALSE | AA5: 3 | AD5: 46254 | AE5: c4e3d6e4936d4ba5a5dbe6b964e7be20 | AF5: collect:9AAIFDC3ZZP7ATGn | AG5: feminin | AH5: 44 | AI5: femme_enceinte_allaitante menage_monoparental | AJ5: kit_abri | AK5: non | AL5: oui | AM5: non | AN5: satisfait | AO5: oui | AP5: non | AQ5: oui | AR5: non | AS5: aucune | AT5: aucune | AU5: dirianatins | AV5: 46254.381

Sheet Data_Clean
A1: id | B1: date | C1: zone | D1: secteur | E1: localite | F1: code_menage | G1: sexe | H1: age | I1: age_group | J1: statut_repondant | K1: vulnerabilite | L1: vulnerable_flag | M1: type_assistance | N1: satisfaction_txt | O1: satisfaction_score | P1: bien_utilise_txt | Q1: bien_utilise_flag | R1: connait_mecanisme_txt | S1: connait_mecanisme_flag | T1: utilise_mecanisme_txt | U1: utilise_mecanisme_flag | V1: acces_equitable_flag | W1: securite_distribution_flag | X1: priorite_vulnerables_flag | Y1: dignite_traitement_flag | Z1: recommandation_flag | AA1: info_disponible_flag | AB1: adequation_besoins_flag | AC1: uuid | AD1: dup_key | AE1: is_duplicate | AF1: missing_fields_flag | AG1: has_row
A2: =IF(Raw_Data!B5="","",Raw_Data!B5) -> 46254 | B2: =IF(Raw_Data!X5<>"",Raw_Data!X5,Raw_Data!C5) -> [] | C2: =IF(Raw_Data!G5="","",Raw_Data!G5) -> sante | D2: =IF(Raw_Data!H5="","",Raw_Data!H5) -> tena kidy | E2: =IF(Raw_Data!I5="","",Raw_Data!I5) | F2: =IF(Raw_Data!J5="","",Raw_Data!J5) -> feminin | G2: =IF(Raw_Data!AH5<>"",Raw_Data!AH5,IF(Raw_Data!K5<>"",Raw_Data!K5,"")) -> 44 | H2: =IF(Raw_Data!AI5<>"",Raw_Data!AI5,IF(Raw_Data!L5<>"",Raw_Data!L5,"")) -> femme_enceinte_allaitante menage_monoparental | I2: =IF(H2="","",IF(H2<18,"<18 ans",IF(H2<60,"18-59 ans","60 ans et +"))) -> 60 ans et + | J2: =IF(Raw_Data!M5="","",Raw_Data!M5) -> femme_enceinte_allaitante menage_monoparental | K2: =IF(Raw_Data!AJ5<>"",Raw_Data!AJ5,Raw_Data!N5) -> kit_abri | L2: =IF(K2="",0,1) -> 1 | M2: =IF(Raw_Data!AK5="","",Raw_Data!AK5) -> non | N2: =IF(Raw_Data!T5="","",Raw_Data!T5) -> satisfait | O2: =IF(Raw_Data!AB5<>"",Raw_Data!AB5,IF(N2="tres_insatisfait",1,IF(N2="insatisfait",2,IF(N2="neutre",3,IF(N2="satisfait",4,IF(N2="tres_satisfait",5,"")))))) -> 4 | P2: =IF(Raw_Data!AL5<>"",Raw_Data!AL5,Raw_Data!R5) -> oui | Q2: =IF(P2="","",IF(P2="oui",1,0)) -> 1 | R2: =IF(Raw_Data!AM5="","",Raw_Data!AM5) -> non | S2: =IF(R2="","",IF(R2="oui",1,0)) -> 0 | T2: =IF(Raw_Data!AN5="","",Raw_Data!AN5) -> satisfait | U2: =IF(T2="","",IF(T2="oui",1,0)) -> 0 | V2: =IF(Raw_Data!AP5="","",IF(Raw_Data!AP5="oui",1,0)) -> 0 | W2: =IF(Raw_Data!AQ5="","",IF(Raw_Data!AQ5="oui",1,0)) -> 1 | X2: =IF(Raw_Data!AR5="","",IF(Raw_Data!AR5="oui",1,0)) -> 0 | Y2: =IF(Raw_Data!AS5="","",IF(Raw_Data!AS5="oui",1,0)) -> 0 | Z2: =IF(Raw_Data!V5="","",IF(Raw_Data!V5="oui",1,0)) -> 1 | AA2: =IF(Raw_Data!W5="","",IF(Raw_Data!W5="oui",1,0)) -> 0 | AB2: =IF(Raw_Data!Q5="","",IF(Raw_Data!Q5="oui",1,0)) -> 1 | AC2: =Raw_Data!AF5 -> collect:9AAIFDC3ZZP7ATGn | AD2: =IF(A2="","",F2&"|"&E2&"|"&TEXT(B2,"YYYY-MM-DD")) -> feminin||[] | AE2: =IF(AD2="","",IF(COUNTIF($AD$2:$AD$1000,AD2)>1,1,0)) -> 0 | AF2: =IF(A2="","",IF(OR(C2="",D2="",G2="",H2="",N2=""),1,0)) -> 0 | AG2: =IF(A2="",0,1) -> 1
A3: =IF(Raw_Data!B6="","",Raw_Data!B6) | B3: =IF(Raw_Data!X6<>"",Raw_Data!X6,Raw_Data!C6) -> 0 | C3: =IF(Raw_Data!G6="","",Raw_Data!G6) | D3: =IF(Raw_Data!H6="","",Raw_Data!H6) | E3: =IF(Raw_Data!I6="","",Raw_Data!I6) | F3: =IF(Raw_Data!J6="","",Raw_Data!J6) | G3: =IF(Raw_Data!AH6<>"",Raw_Data!AH6,IF(Raw_Data!K6<>"",Raw_Data!K6,"")) | H3: =IF(Raw_Data!AI6<>"",Raw_Data!AI6,IF(Raw_Data!L6<>"",Raw_Data!L6,"")) | I3: =IF(H3="","",IF(H3<18,"<18 ans",IF(H3<60,"18-59 ans","60 ans et +"))) | J3: =IF(Raw_Data!M6="","",Raw_Data!M6) | K3: =IF(Raw_Data!AJ6<>"",Raw_Data!AJ6,Raw_Data!N6) -> 0 | L3: =IF(K3="",0,1) -> 1 | M3: =IF(Raw_Data!AK6="","",Raw_Data!AK6) | N3: =IF(Raw_Data!T6="","",Raw_Data!T6) | O3: =IF(Raw_Data!AB6<>"",Raw_Data!AB6,IF(N3="tres_insatisfait",1,IF(N3="insatisfait",2,IF(N3="neutre",3,IF(N3="satisfait",4,IF(N3="tres_satisfait",5,"")))))) | P3: =IF(Raw_Data!AL6<>"",Raw_Data!AL6,Raw_Data!R6) -> 0 | Q3: =IF(P3="","",IF(P3="oui",1,0)) -> 0 | R3: =IF(Raw_Data!AM6="","",Raw_Data!AM6) | S3: =IF(R3="","",IF(R3="oui",1,0)) | T3: =IF(Raw_Data!AN6="","",Raw_Data!AN6) | U3: =IF(T3="","",IF(T3="oui",1,0)) | V3: =IF(Raw_Data!AP6="","",IF(Raw_Data!AP6="oui",1,0)) | W3: =IF(Raw_Data!AQ6="","",IF(Raw_Data!AQ6="oui",1,0)) | X3: =IF(Raw_Data!AR6="","",IF(Raw_Data!AR6="oui",1,0)) | Y3: =IF(Raw_Data!AS6="","",IF(Raw_Data!AS6="oui",1,0)) | Z3: =IF(Raw_Data!V6="","",IF(Raw_Data!V6="oui",1,0)) | AA3: =IF(Raw_Data!W6="","",IF(Raw_Data!W6="oui",1,0)) | AB3: =IF(Raw_Data!Q6="","",IF(Raw_Data!Q6="oui",1,0)) | AC3: =Raw_Data!AF6 -> 0 | AD3: =IF(A3="","",F3&"|"&E3&"|"&TEXT(B3,"YYYY-MM-DD")) | AE3: =IF(AD3="","",IF(COUNTIF($AD$2:$AD$1000,AD3)>1,1,0)) | AF3: =IF(A3="","",IF(OR(C3="",D3="",G3="",H3="",N3=""),1,0)) | AG3: =IF(A3="",0,1) -> 0
A4: =IF(Raw_Data!B7="","",Raw_Data!B7) | B4: =IF(Raw_Data!X7<>"",Raw_Data!X7,Raw_Data!C7) -> 0 | C4: =IF(Raw_Data!G7="","",Raw_Data!G7) | D4: =IF(Raw_Data!H7="","",Raw_Data!H7) | E4: =IF(Raw_Data!I7="","",Raw_Data!I7) | F4: =IF(Raw_Data!J7="","",Raw_Data!J7) | G4: =IF(Raw_Data!AH7<>"",Raw_Data!AH7,IF(Raw_Data!K7<>"",Raw_Data!K7,"")) | H4: =IF(Raw_Data!AI7<>"",Raw_Data!AI7,IF(Raw_Data!L7<>"",Raw_Data!L7,"")) | I4: =IF(H4="","",IF(H4<18,"<18 ans",IF(H4<60,"18-59 ans","60 ans et +"))) | J4: =IF(Raw_Data!M7="","",Raw_Data!M7) | K4: =IF(Raw_Data!AJ7<>"",Raw_Data!AJ7,Raw_Data!N7) -> 0 | L4: =IF(K4="",0,1) -> 1 | M4: =IF(Raw_Data!AK7="","",Raw_Data!AK7) | N4: =IF(Raw_Data!T7="","",Raw_Data!T7) | O4: =IF(Raw_Data!AB7<>"",Raw_Data!AB7,IF(N4="tres_insatisfait",1,IF(N4="insatisfait",2,IF(N4="neutre",3,IF(N4="satisfait",4,IF(N4="tres_satisfait",5,"")))))) | P4: =IF(Raw_Data!AL7<>"",Raw_Data!AL7,Raw_Data!R7) -> 0 | Q4: =IF(P4="","",IF(P4="oui",1,0)) -> 0 | R4: =IF(Raw_Data!AM7="","",Raw_Data!AM7) | S4: =IF(R4="","",IF(R4="oui",1,0)) | T4: =IF(Raw_Data!AN7="","",Raw_Data!AN7) | U4: =IF(T4="","",IF(T4="oui",1,0)) | V4: =IF(Raw_Data!AP7="","",IF(Raw_Data!AP7="oui",1,0)) | W4: =IF(Raw_Data!AQ7="","",IF(Raw_Data!AQ7="oui",1,0)) | X4: =IF(Raw_Data!AR7="","",IF(Raw_Data!AR7="oui",1,0)) | Y4: =IF(Raw_Data!AS7="","",IF(Raw_Data!AS7="oui",1,0)) | Z4: =IF(Raw_Data!V7="","",IF(Raw_Data!V7="oui",1,0)) | AA4: =IF(Raw_Data!W7="","",IF(Raw_Data!W7="oui",1,0)) | AB4: =IF(Raw_Data!Q7="","",IF(Raw_Data!Q7="oui",1,0)) | AC4: =Raw_Data!AF7 -> 0 | AD4: =IF(A4="","",F4&"|"&E4&"|"&TEXT(B4,"YYYY-MM-DD")) | AE4: =IF(AD4="","",IF(COUNTIF($AD$2:$AD$1000,AD4)>1,1,0)) | AF4: =IF(A4="","",IF(OR(C4="",D4="",G4="",H4="",N4=""),1,0)) | AG4: =IF(A4="",0,1) -> 0
A5: =IF(Raw_Data!B8="","",Raw_Data!B8) | B5: =IF(Raw_Data!X8<>"",Raw_Data!X8,Raw_Data!C8) -> 0 | C5: =IF(Raw_Data!G8="","",Raw_Data!G8) | D5: =IF(Raw_Data!H8="","",Raw_Data!H8) | E5: =IF(Raw_Data!I8="","",Raw_Data!I8) | F5: =IF(Raw_Data!J8="","",Raw_Data!J8) | G5: =IF(Raw_Data!AH8<>"",Raw_Data!AH8,IF(Raw_Data!K8<>"",Raw_Data!K8,"")) | H5: =IF(Raw_Data!AI8<>"",Raw_Data!AI8,IF(Raw_Data!L8<>"",Raw_Data!L8,"")) | I5: =IF(H5="","",IF(H5<18,"<18 ans",IF(H5<60,"18-59 ans","60 ans et +"))) | J5: =IF(Raw_Data!M8="","",Raw_Data!M8) | K5: =IF(Raw_Data!AJ8<>"",Raw_Data!AJ8,Raw_Data!N8) -> 0 | L5: =IF(K5="",0,1) -> 1 | M5: =IF(Raw_Data!AK8="","",Raw_Data!AK8) | N5: =IF(Raw_Data!T8="","",Raw_Data!T8) | O5: =IF(Raw_Data!AB8<>"",Raw_Data!AB8,IF(N5="tres_insatisfait",1,IF(N5="insatisfait",2,IF(N5="neutre",3,IF(N5="satisfait",4,IF(N5="tres_satisfait",5,"")))))) | P5: =IF(Raw_Data!AL8<>"",Raw_Data!AL8,Raw_Data!R8) -> 0 | Q5: =IF(P5="","",IF(P5="oui",1,0)) -> 0 | R5: =IF(Raw_Data!AM8="","",Raw_Data!AM8) | S5: =IF(R5="","",IF(R5="oui",1,0)) | T5: =IF(Raw_Data!AN8="","",Raw_Data!AN8) | U5: =IF(T5="","",IF(T5="oui",1,0)) | V5: =IF(Raw_Data!AP8="","",IF(Raw_Data!AP8="oui",1,0)) | W5: =IF(Raw_Data!AQ8="","",IF(Raw_Data!AQ8="oui",1,0)) | X5: =IF(Raw_Data!AR8="","",IF(Raw_Data!AR8="oui",1,0)) | Y5: =IF(Raw_Data!AS8="","",IF(Raw_Data!AS8="oui",1,0)) | Z5: =IF(Raw_Data!V8="","",IF(Raw_Data!V8="oui",1,0)) | AA5: =IF(Raw_Data!W8="","",IF(Raw_Data!W8="oui",1,0)) | AB5: =IF(Raw_Data!Q8="","",IF(Raw_Data!Q8="oui",1,0)) | AC5: =Raw_Data!AF8 -> 0 | AD5: =IF(A5="","",F5&"|"&E5&"|"&TEXT(B5,"YYYY-MM-DD")) | AE5: =IF(AD5="","",IF(COUNTIF($AD$2:$AD$1000,AD5)>1,1,0)) | AF5: =IF(A5="","",IF(OR(C5="",D5="",G5="",H5="",N5=""),1,0)) | AG5: =IF(A5="",0,1) -> 0
A6: =IF(Raw_Data!B9="","",Raw_Data!B9) | B6: =IF(Raw_Data!X9<>"",Raw_Data!X9,Raw_Data!C9) -> 0 | C6: =IF(Raw_Data!G9="","",Raw_Data!G9) | D6: =IF(Raw_Data!H9="","",Raw_Data!H9) | E6: =IF(Raw_Data!I9="","",Raw_Data!I9) | F6: =IF(Raw_Data!J9="","",Raw_Data!J9) | G6: =IF(Raw_Data!AH9<>"",Raw_Data!AH9,IF(Raw_Data!K9<>"",Raw_Data!K9,"")) | H6: =IF(Raw_Data!AI9<>"",Raw_Data!AI9,IF(Raw_Data!L9<>"",Raw_Data!L9,"")) | I6: =IF(H6="","",IF(H6<18,"<18 ans",IF(H6<60,"18-59 ans","60 ans et +"))) | J6: =IF(Raw_Data!M9="","",Raw_Data!M9) | K6: =IF(Raw_Data!AJ9<>"",Raw_Data!AJ9,Raw_Data!N9) -> 0 | L6: =IF(K6="",0,1) -> 1 | M6: =IF(Raw_Data!AK9="","",Raw_Data!AK9) | N6: =IF(Raw_Data!T9="","",Raw_Data!T9) | O6: =IF(Raw_Data!AB9<>"",Raw_Data!AB9,IF(N6="tres_insatisfait",1,IF(N6="insatisfait",2,IF(N6="neutre",3,IF(N6="satisfait",4,IF(N6="tres_satisfait",5,"")))))) | P6: =IF(Raw_Data!AL9<>"",Raw_Data!AL9,Raw_Data!R9) -> 0 | Q6: =IF(P6="","",IF(P6="oui",1,0)) -> 0 | R6: =IF(Raw_Data!AM9="","",Raw_Data!AM9) | S6: =IF(R6="","",IF(R6="oui",1,0)) | T6: =IF(Raw_Data!AN9="","",Raw_Data!AN9) | U6: =IF(T6="","",IF(T6="oui",1,0)) | V6: =IF(Raw_Data!AP9="","",IF(Raw_Data!AP9="oui",1,0)) | W6: =IF(Raw_Data!AQ9="","",IF(Raw_Data!AQ9="oui",1,0)) | X6: =IF(Raw_Data!AR9="","",IF(Raw_Data!AR9="oui",1,0)) | Y6: =IF(Raw_Data!AS9="","",IF(Raw_Data!AS9="oui",1,0)) | Z6: =IF(Raw_Data!V9="","",IF(Raw_Data!V9="oui",1,0)) | AA6: =IF(Raw_Data!W9="","",IF(Raw_Data!W9="oui",1,0)) | AB6: =IF(Raw_Data!Q9="","",IF(Raw_Data!Q9="oui",1,0)) | AC6: =Raw_Data!AF9 -> 0 | AD6: =IF(A6="","",F6&"|"&E6&"|"&TEXT(B6,"YYYY-MM-DD")) | AE6: =IF(AD6="","",IF(COUNTIF($AD$2:$AD$1000,AD6)>1,1,0)) | AF6: =IF(A6="","",IF(OR(C6="",D6="",G6="",H6="",N6=""),1,0)) | AG6: =IF(A6="",0,1) -> 0
A7: =IF(Raw_Data!B10="","",Raw_Data!B10) | B7: =IF(Raw_Data!X10<>"",Raw_Data!X10,Raw_Data!C10) -> 0 | C7: =IF(Raw_Data!G10="","",Raw_Data!G10) | D7: =IF(Raw_Data!H10="","",Raw_Data!H10) | E7: =IF(Raw_Data!I10="","",Raw_Data!I10) | F7: =IF(Raw_Data!J10="","",Raw_Data!J10) | G7: =IF(Raw_Data!AH10<>"",Raw_Data!AH10,IF(Raw_Data!K10<>"",Raw_Data!K10,"")) | H7: =IF(Raw_Data!AI10<>"",Raw_Data!AI10,IF(Raw_Data!L10<>"",Raw_Data!L10,"")) | I7: =IF(H7="","",IF(H7<18,"<18 ans",IF(H7<60,"18-59 ans","60 ans et +"))) | J7: =IF(Raw_Data!M10="","",Raw_Data!M10) | K7: =IF(Raw_Data!AJ10<>"",Raw_Data!AJ10,Raw_Data!N10) -> 0 | L7: =IF(K7="",0,1) -> 1 | M7: =IF(Raw_Data!AK10="","",Raw_Data!AK10) | N7: =IF(Raw_Data!T10="","",Raw_Data!T10) | O7: =IF(Raw_Data!AB10<>"",Raw_Data!AB10,IF(N7="tres_insatisfait",1,IF(N7="insatisfait",2,IF(N7="neutre",3,IF(N7="satisfait",4,IF(N7="tres_satisfait",5,"")))))) | P7: =IF(Raw_Data!AL10<>"",Raw_Data!AL10,Raw_Data!R10) -> 0 | Q7: =IF(P7="","",IF(P7="oui",1,0)) -> 0 | R7: =IF(Raw_Data!AM10="","",Raw_Data!AM10) | S7: =IF(R7="","",IF(R7="oui",1,0)) | T7: =IF(Raw_Data!AN10="","",Raw_Data!AN10) | U7: =IF(T7="","",IF(T7="oui",1,0)) | V7: =IF(Raw_Data!AP10="","",IF(Raw_Data!AP10="oui",1,0)) | W7: =IF(Raw_Data!AQ10="","",IF(Raw_Data!AQ10="oui",1,0)) | X7: =IF(Raw_Data!AR10="","",IF(Raw_Data!AR10="oui",1,0)) | Y7: =IF(Raw_Data!AS10="","",IF(Raw_Data!AS10="oui",1,0)) | Z7: =IF(Raw_Data!V10="","",IF(Raw_Data!V10="oui",1,0)) | AA7: =IF(Raw_Data!W10="","",IF(Raw_Data!W10="oui",1,0)) | AB7: =IF(Raw_Data!Q10="","",IF(Raw_Data!Q10="oui",1,0)) | AC7: =Raw_Data!AF10 -> 0 | AD7: =IF(A7="","",F7&"|"&E7&"|"&TEXT(B7,"YYYY-MM-DD")) | AE7: =IF(AD7="","",IF(COUNTIF($AD$2:$AD$1000,AD7)>1,1,0)) | AF7: =IF(A7="","",IF(OR(C7="",D7="",G7="",H7="",N7=""),1,0)) | AG7: =IF(A7="",0,1) -> 0
A8: =IF(Raw_Data!B11="","",Raw_Data!B11) | B8: =IF(Raw_Data!X11<>"",Raw_Data!X11,Raw_Data!C11) -> 0 | C8: =IF(Raw_Data!G11="","",Raw_Data!G11) | D8: =IF(Raw_Data!H11="","",Raw_Data!H11) | E8: =IF(Raw_Data!I11="","",Raw_Data!I11) | F8: =IF(Raw_Data!J11="","",Raw_Data!J11) | G8: =IF(Raw_Data!AH11<>"",Raw_Data!AH11,IF(Raw_Data!K11<>"",Raw_Data!K11,"")) | H8: =IF(Raw_Data!AI11<>"",Raw_Data!AI11,IF(Raw_Data!L11<>"",Raw_Data!L11,"")) | I8: =IF(H8="","",IF(H8<18,"<18 ans",IF(H8<60,"18-59 ans","60 ans et +"))) | J8: =IF(Raw_Data!M11="","",Raw_Data!M11) | K8: =IF(Raw_Data!AJ11<>"",Raw_Data!AJ11,Raw_Data!N11) -> 0 | L8: =IF(K8="",0,1) -> 1 | M8: =IF(Raw_Data!AK11="","",Raw_Data!AK11) | N8: =IF(Raw_Data!T11="","",Raw_Data!T11) | O8: =IF(Raw_Data!AB11<>"",Raw_Data!AB11,IF(N8="tres_insatisfait",1,IF(N8="insatisfait",2,IF(N8="neutre",3,IF(N8="satisfait",4,IF(N8="tres_satisfait",5,"")))))) | P8: =IF(Raw_Data!AL11<>"",Raw_Data!AL11,Raw_Data!R11) -> 0 | Q8: =IF(P8="","",IF(P8="oui",1,0)) -> 0 | R8: =IF(Raw_Data!AM11="","",Raw_Data!AM11) | S8: =IF(R8="","",IF(R8="oui",1,0)) | T8: =IF(Raw_Data!AN11="","",Raw_Data!AN11) | U8: =IF(T8="","",IF(T8="oui",1,0)) | V8: =IF(Raw_Data!AP11="","",IF(Raw_Data!AP11="oui",1,0)) | W8: =IF(Raw_Data!AQ11="","",IF(Raw_Data!AQ11="oui",1,0)) | X8: =IF(Raw_Data!AR11="","",IF(Raw_Data!AR11="oui",1,0)) | Y8: =IF(Raw_Data!AS11="","",IF(Raw_Data!AS11="oui",1,0)) | Z8: =IF(Raw_Data!V11="","",IF(Raw_Data!V11="oui",1,0)) | AA8: =IF(Raw_Data!W11="","",IF(Raw_Data!W11="oui",1,0)) | AB8: =IF(Raw_Data!Q11="","",IF(Raw_Data!Q11="oui",1,0)) | AC8: =Raw_Data!AF11 -> 0 | AD8: =IF(A8="","",F8&"|"&E8&"|"&TEXT(B8,"YYYY-MM-DD")) | AE8: =IF(AD8="","",IF(COUNTIF($AD$2:$AD$1000,AD8)>1,1,0)) | AF8: =IF(A8="","",IF(OR(C8="",D8="",G8="",H8="",N8=""),1,0)) | AG8: =IF(A8="",0,1) -> 0
A9: =IF(Raw_Data!B12="","",Raw_Data!B12) | B9: =IF(Raw_Data!X12<>"",Raw_Data!X12,Raw_Data!C12) -> 0 | C9: =IF(Raw_Data!G12="","",Raw_Data!G12) | D9: =IF(Raw_Data!H12="","",Raw_Data!H12) | E9: =IF(Raw_Data!I12="","",Raw_Data!I12) | F9: =IF(Raw_Data!J12="","",Raw_Data!J12) | G9: =IF(Raw_Data!AH12<>"",Raw_Data!AH12,IF(Raw_Data!K12<>"",Raw_Data!K12,"")) | H9: =IF(Raw_Data!AI12<>"",Raw_Data!AI12,IF(Raw_Data!L12<>"",Raw_Data!L12,"")) | I9: =IF(H9="","",IF(H9<18,"<18 ans",IF(H9<60,"18-59 ans","60 ans et +"))) | J9: =IF(Raw_Data!M12="","",Raw_Data!M12) | K9: =IF(Raw_Data!AJ12<>"",Raw_Data!AJ12,Raw_Data!N12) -> 0 | L9: =IF(K9="",0,1) -> 1 | M9: =IF(Raw_Data!AK12="","",Raw_Data!AK12) | N9: =IF(Raw_Data!T12="","",Raw_Data!T12) | O9: =IF(Raw_Data!AB12<>"",Raw_Data!AB12,IF(N9="tres_insatisfait",1,IF(N9="insatisfait",2,IF(N9="neutre",3,IF(N9="satisfait",4,IF(N9="tres_satisfait",5,"")))))) | P9: =IF(Raw_Data!AL12<>"",Raw_Data!AL12,Raw_Data!R12) -> 0 | Q9: =IF(P9="","",IF(P9="oui",1,0)) -> 0 | R9: =IF(Raw_Data!AM12="","",Raw_Data!AM12) | S9: =IF(R9="","",IF(R9="oui",1,0)) | T9: =IF(Raw_Data!AN12="","",Raw_Data!AN12) | U9: =IF(T9="","",IF(T9="oui",1,0)) | V9: =IF(Raw_Data!AP12="","",IF(Raw_Data!AP12="oui",1,0)) | W9: =IF(Raw_Data!AQ12="","",IF(Raw_Data!AQ12="oui",1,0)) | X9: =IF(Raw_Data!AR12="","",IF(Raw_Data!AR12="oui",1,0)) | Y9: =IF(Raw_Data!AS12="","",IF(Raw_Data!AS12="oui",1,0)) | Z9: =IF(Raw_Data!V12="","",IF(Raw_Data!V12="oui",1,0)) | AA9: =IF(Raw_Data!W12="","",IF(Raw_Data!W12="oui",1,0)) | AB9: =IF(Raw_Data!Q12="","",IF(Raw_Data!Q12="oui",1,0)) | AC9: =Raw_Data!AF12 -> 0 | AD9: =IF(A9="","",F9&"|"&E9&"|"&TEXT(B9,"YYYY-MM-DD")) | AE9: =IF(AD9="","",IF(COUNTIF($AD$2:$AD$1000,AD9)>1,1,0)) | AF9: =IF(A9="","",IF(OR(C9="",D9="",G9="",H9="",N9=""),1,0)) | AG9: =IF(A9="",0,1) -> 0
A10: =IF(Raw_Data!B13="","",Raw_Data!B13) | B10: =IF(Raw_Data!X13<>"",Raw_Data!X13,Raw_Data!C13) -> 0 | C10: =IF(Raw_Data!G13="","",Raw_Data!G13) | D10: =IF(Raw_Data!H13="","",Raw_Data!H13) | E10: =IF(Raw_Data!I13="","",Raw_Data!I13) | F10: =IF(Raw_Data!J13="","",Raw_Data!J13) | G10: =IF(Raw_Data!AH13<>"",Raw_Data!AH13,IF(Raw_Data!K13<>"",Raw_Data!K13,"")) | H10: =IF(Raw_Data!AI13<>"",Raw_Data!AI13,IF(Raw_Data!L13<>"",Raw_Data!L13,"")) | I10: =IF(H10="","",IF(H10<18,"<18 ans",IF(H10<60,"18-59 ans","60 ans et +"))) | J10: =IF(Raw_Data!M13="","",Raw_Data!M13) | K10: =IF(Raw_Data!AJ13<>"",Raw_Data!AJ13,Raw_Data!N13) -> 0 | L10: =IF(K10="",0,1) -> 1 | M10: =IF(Raw_Data!AK13="","",Raw_Data!AK13) | N10: =IF(Raw_Data!T13="","",Raw_Data!T13) | O10: =IF(Raw_Data!AB13<>"",Raw_Data!AB13,IF(N10="tres_insatisfait",1,IF(N10="insatisfait",2,IF(N10="neutre",3,IF(N10="satisfait",4,IF(N10="tres_satisfait",5,"")))))) | P10: =IF(Raw_Data!AL13<>"",Raw_Data!AL13,Raw_Data!R13) -> 0 | Q10: =IF(P10="","",IF(P10="oui",1,0)) -> 0 | R10: =IF(Raw_Data!AM13="","",Raw_Data!AM13) | S10: =IF(R10="","",IF(R10="oui",1,0)) | T10: =IF(Raw_Data!AN13="","",Raw_Data!AN13) | U10: =IF(T10="","",IF(T10="oui",1,0)) | V10: =IF(Raw_Data!AP13="","",IF(Raw_Data!AP13="oui",1,0)) | W10: =IF(Raw_Data!AQ13="","",IF(Raw_Data!AQ13="oui",1,0)) | X10: =IF(Raw_Data!AR13="","",IF(Raw_Data!AR13="oui",1,0)) | Y10: =IF(Raw_Data!AS13="","",IF(Raw_Data!AS13="oui",1,0)) | Z10: =IF(Raw_Data!V13="","",IF(Raw_Data!V13="oui",1,0)) | AA10: =IF(Raw_Data!W13="","",IF(Raw_Data!W13="oui",1,0)) | AB10: =IF(Raw_Data!Q13="","",IF(Raw_Data!Q13="oui",1,0)) | AC10: =Raw_Data!AF13 -> 0 | AD10: =IF(A10="","",F10&"|"&E10&"|"&TEXT(B10,"YYYY-MM-DD")) | AE10: =IF(AD10="","",IF(COUNTIF($AD$2:$AD$1000,AD10)>1,1,0)) | AF10: =IF(A10="","",IF(OR(C10="",D10="",G10="",H10="",N10=""),1,0)) | AG10: =IF(A10="",0,1) -> 0
A11: =IF(Raw_Data!B14="","",Raw_Data!B14) | B11: =IF(Raw_Data!X14<>"",Raw_Data!X14,Raw_Data!C14) -> 0 | C11: =IF(Raw_Data!G14="","",Raw_Data!G14) | D11: =IF(Raw_Data!H14="","",Raw_Data!H14) | E11: =IF(Raw_Data!I14="","",Raw_Data!I14) | F11: =IF(Raw_Data!J14="","",Raw_Data!J14) | G11: =IF(Raw_Data!AH14<>"",Raw_Data!AH14,IF(Raw_Data!K14<>"",Raw_Data!K14,"")) | H11: =IF(Raw_Data!AI14<>"",Raw_Data!AI14,IF(Raw_Data!L14<>"",Raw_Data!L14,"")) | I11: =IF(H11="","",IF(H11<18,"<18 ans",IF(H11<60,"18-59 ans","60 ans et +"))) | J11: =IF(Raw_Data!M14="","",Raw_Data!M14) | K11: =IF(Raw_Data!AJ14<>"",Raw_Data!AJ14,Raw_Data!N14) -> 0 | L11: =IF(K11="",0,1) -> 1 | M11: =IF(Raw_Data!AK14="","",Raw_Data!AK14) | N11: =IF(Raw_Data!T14="","",Raw_Data!T14) | O11: =IF(Raw_Data!AB14<>"",Raw_Data!AB14,IF(N11="tres_insatisfait",1,IF(N11="insatisfait",2,IF(N11="neutre",3,IF(N11="satisfait",4,IF(N11="tres_satisfait",5,"")))))) | P11: =IF(Raw_Data!AL14<>"",Raw_Data!AL14,Raw_Data!R14) -> 0 | Q11: =IF(P11="","",IF(P11="oui",1,0)) -> 0 | R11: =IF(Raw_Data!AM14="","",Raw_Data!AM14) | S11: =IF(R11="","",IF(R11="oui",1,0)) | T11: =IF(Raw_Data!AN14="","",Raw_Data!AN14) | U11: =IF(T11="","",IF(T11="oui",1,0)) | V11: =IF(Raw_Data!AP14="","",IF(Raw_Data!AP14="oui",1,0)) | W11: =IF(Raw_Data!AQ14="","",IF(Raw_Data!AQ14="oui",1,0)) | X11: =IF(Raw_Data!AR14="","",IF(Raw_Data!AR14="oui",1,0)) | Y11: =IF(Raw_Data!AS14="","",IF(Raw_Data!AS14="oui",1,0)) | Z11: =IF(Raw_Data!V14="","",IF(Raw_Data!V14="oui",1,0)) | AA11: =IF(Raw_Data!W14="","",IF(Raw_Data!W14="oui",1,0)) | AB11: =IF(Raw_Data!Q14="","",IF(Raw_Data!Q14="oui",1,0)) | AC11: =Raw_Data!AF14 -> 0 | AD11: =IF(A11="","",F11&"|"&E11&"|"&TEXT(B11,"YYYY-MM-DD")) | AE11: =IF(AD11="","",IF(COUNTIF($AD$2:$AD$1000,AD11)>1,1,0)) | AF11: =IF(A11="","",IF(OR(C11="",D11="",G11="",H11="",N11=""),1,0)) | AG11: =IF(A11="",0,1) -> 0
A12: =IF(Raw_Data!B15="","",Raw_Data!B15) | B12: =IF(Raw_Data!X15<>"",Raw_Data!X15,Raw_Data!C15) -> 0 | C12: =IF(Raw_Data!G15="","",Raw_Data!G15) | D12: =IF(Raw_Data!H15="","",Raw_Data!H15) | E12: =IF(Raw_Data!I15="","",Raw_Data!I15) | F12: =IF(Raw_Data!J15="","",Raw_Data!J15) | G12: =IF(Raw_Data!AH15<>"",Raw_Data!AH15,IF(Raw_Data!K15<>"",Raw_Data!K15,"")) | H12: =IF(Raw_Data!AI15<>"",Raw_Data!AI15,IF(Raw_Data!L15<>"",Raw_Data!L15,"")) | I12: =IF(H12="","",IF(H12<18,"<18 ans",IF(H12<60,"18-59 ans","60 ans et +"))) | J12: =IF(Raw_Data!M15="","",Raw_Data!M15) | K12: =IF(Raw_Data!AJ15<>"",Raw_Data!AJ15,Raw_Data!N15) -> 0 | L12: =IF(K12="",0,1) -> 1 | M12: =IF(Raw_Data!AK15="","",Raw_Data!AK15) | N12: =IF(Raw_Data!T15="","",Raw_Data!T15) | O12: =IF(Raw_Data!AB15<>"",Raw_Data!AB15,IF(N12="tres_insatisfait",1,IF(N12="insatisfait",2,IF(N12="neutre",3,IF(N12="satisfait",4,IF(N12="tres_satisfait",5,"")))))) | P12: =IF(Raw_Data!AL15<>"",Raw_Data!AL15,Raw_Data!R15) -> 0 | Q12: =IF(P12="","",IF(P12="oui",1,0)) -> 0 | R12: =IF(Raw_Data!AM15="","",Raw_Data!AM15) | S12: =IF(R12="","",IF(R12="oui",1,0)) | T12: =IF(Raw_Data!AN15="","",Raw_Data!AN15) | U12: =IF(T12="","",IF(T12="oui",1,0)) | V12: =IF(Raw_Data!AP15="","",IF(Raw_Data!AP15="oui",1,0)) | W12: =IF(Raw_Data!AQ15="","",IF(Raw_Data!AQ15="oui",1,0)) | X12: =IF(Raw_Data!AR15="","",IF(Raw_Data!AR15="oui",1,0)) | Y12: =IF(Raw_Data!AS15="","",IF(Raw_Data!AS15="oui",1,0)) | Z12: =IF(Raw_Data!V15="","",IF(Raw_Data!V15="oui",1,0)) | AA12: =IF(Raw_Data!W15="","",IF(Raw_Data!W15="oui",1,0)) | AB12: =IF(Raw_Data!Q15="","",IF(Raw_Data!Q15="oui",1,0)) | AC12: =Raw_Data!AF15 -> 0 | AD12: =IF(A12="","",F12&"|"&E12&"|"&TEXT(B12,"YYYY-MM-DD")) | AE12: =IF(AD12="","",IF(COUNTIF($AD$2:$AD$1000,AD12)>1,1,0)) | AF12: =IF(A12="","",IF(OR(C12="",D12="",G12="",H12="",N12=""),1,0)) | AG12: =IF(A12="",0,1) -> 0
A13: =IF(Raw_Data!B16="","",Raw_Data!B16) | B13: =IF(Raw_Data!X16<>"",Raw_Data!X16,Raw_Data!C16) -> 0 | C13: =IF(Raw_Data!G16="","",Raw_Data!G16) | D13: =IF(Raw_Data!H16="","",Raw_Data!H16) | E13: =IF(Raw_Data!I16="","",Raw_Data!I16) | F13: =IF(Raw_Data!J16="","",Raw_Data!J16) | G13: =IF(Raw_Data!AH16<>"",Raw_Data!AH16,IF(Raw_Data!K16<>"",Raw_Data!K16,"")) | H13: =IF(Raw_Data!AI16<>"",Raw_Data!AI16,IF(Raw_Data!L16<>"",Raw_Data!L16,"")) | I13: =IF(H13="","",IF(H13<18,"<18 ans",IF(H13<60,"18-59 ans","60 ans et +"))) | J13: =IF(Raw_Data!M16="","",Raw_Data!M16) | K13: =IF(Raw_Data!AJ16<>"",Raw_Data!AJ16,Raw_Data!N16) -> 0 | L13: =IF(K13="",0,1) -> 1 | M13: =IF(Raw_Data!AK16="","",Raw_Data!AK16) | N13: =IF(Raw_Data!T16="","",Raw_Data!T16) | O13: =IF(Raw_Data!AB16<>"",Raw_Data!AB16,IF(N13="tres_insatisfait",1,IF(N13="insatisfait",2,IF(N13="neutre",3,IF(N13="satisfait",4,IF(N13="tres_satisfait",5,"")))))) | P13: =IF(Raw_Data!AL16<>"",Raw_Data!AL16,Raw_Data!R16) -> 0 | Q13: =IF(P13="","",IF(P13="oui",1,0)) -> 0 | R13: =IF(Raw_Data!AM16="","",Raw_Data!AM16) | S13: =IF(R13="","",IF(R13="oui",1,0)) | T13: =IF(Raw_Data!AN16="","",Raw_Data!AN16) | U13: =IF(T13="","",IF(T13="oui",1,0)) | V13: =IF(Raw_Data!AP16="","",IF(Raw_Data!AP16="oui",1,0)) | W13: =IF(Raw_Data!AQ16="","",IF(Raw_Data!AQ16="oui",1,0)) | X13: =IF(Raw_Data!AR16="","",IF(Raw_Data!AR16="oui",1,0)) | Y13: =IF(Raw_Data!AS16="","",IF(Raw_Data!AS16="oui",1,0)) | Z13: =IF(Raw_Data!V16="","",IF(Raw_Data!V16="oui",1,0)) | AA13: =IF(Raw_Data!W16="","",IF(Raw_Data!W16="oui",1,0)) | AB13: =IF(Raw_Data!Q16="","",IF(Raw_Data!Q16="oui",1,0)) | AC13: =Raw_Data!AF16 -> 0 | AD13: =IF(A13="","",F13&"|"&E13&"|"&TEXT(B13,"YYYY-MM-DD")) | AE13: =IF(AD13="","",IF(COUNTIF($AD$2:$AD$1000,AD13)>1,1,0)) | AF13: =IF(A13="","",IF(OR(C13="",D13="",G13="",H13="",N13=""),1,0)) | AG13: =IF(A13="",0,1) -> 0
... A1000: =IF(Raw_Data!B1003="","",Raw_Data!B1003) | B1000: =IF(Raw_Data!X1003<>"",Raw_Data!X1003,Raw_Data!C1003) -> 0 | C1000: =IF(Raw_Data!G1003="","",Raw_Data!G1003) | D1000: =IF(Raw_Data!H1003="","",Raw_Data!H1003) | E1000: =IF(Raw_Data!I1003="","",Raw_Data!I1003) | F1000: =IF(Raw_Data!J1003="","",Raw_Data!J1003) | G1000: =IF(Raw_Data!AH1003<>"",Raw_Data!AH1003,IF(Raw_Data!K1003<>"",Raw_Data!K1003,"")) | H1000: =IF(Raw_Data!AI1003<>"",Raw_Data!AI1003,IF(Raw_Data!L1003<>"",Raw_Data!L1003,"")) | I1000: =IF(H1000="","",IF(H1000<18,"<18 ans",IF(H1000<60,"18-59 ans","60 ans et +"))) | J1000: =IF(Raw_Data!M1003="","",Raw_Data!M1003) | K1000: =IF(Raw_Data!AJ1003<>"",Raw_Data!AJ1003,Raw_Data!N1003) -> 0 | L1000: =IF(K1000="",0,1) -> 1 | M1000: =IF(Raw_Data!AK1003="","",Raw_Data!AK1003) | N1000: =IF(Raw_Data!T1003="","",Raw_Data!T1003) | O1000: =IF(Raw_Data!AB1003<>"",Raw_Data!AB1003,IF(N1000="tres_insatisfait",1,IF(N1000="insatisfait",2,IF(N1000="neutre",3,IF(N1000="satisfait",4,IF(N1000="tres_satisfait",5,"")))))) | P1000: =IF(Raw_Data!AL1003<>"",Raw_Data!AL1003,Raw_Data!R1003) -> 0 | Q1000: =IF(P1000="","",IF(P1000="oui",1,0)) -> 0 | R1000: =IF(Raw_Data!AM1003="","",Raw_Data!AM1003) | S1000: =IF(R1000="","",IF(R1000="oui",1,0)) | T1000: =IF(Raw_Data!AN1003="","",Raw_Data!AN1003) | U1000: =IF(T1000="","",IF(T1000="oui",1,0)) | V1000: =IF(Raw_Data!AP1003="","",IF(Raw_Data!AP1003="oui",1,0)) | W1000: =IF(Raw_Data!AQ1003="","",IF(Raw_Data!AQ1003="oui",1,0)) | X1000: =IF(Raw_Data!AR1003="","",IF(Raw_Data!AR1003="oui",1,0)) | Y1000: =IF(Raw_Data!AS1003="","",IF(Raw_Data!AS1003="oui",1,0)) | Z1000: =IF(Raw_Data!V1003="","",IF(Raw_Data!V1003="oui",1,0)) | AA1000: =IF(Raw_Data!W1003="","",IF(Raw_Data!W1003="oui",1,0)) | AB1000: =IF(Raw_Data!Q1003="","",IF(Raw_Data!Q1003="oui",1,0)) | AC1000: =Raw_Data!AF1003 -> 0 | AD1000: =IF(A1000="","",F1000&"|"&E1000&"|"&TEXT(B1000,"YYYY-MM-DD")) | AE1000: =IF(AD1000="","",IF(COUNTIF($AD$2:$AD$1000,AD1000)>1,1,0)) | AF1000: =IF(A1000="","",IF(OR(C1000="",D1000="",G1000="",H1000="",N1000=""),1,0)) | AG1000: =IF(A1000="",0,1) -> 0

Sheet QC_Qualite
A1: CONTROLE QUALITE DES DONNEES
A2: Mise a jour automatique a chaque actualisation de Raw_Data
A4: Indicateur de qualite | B4: Valeur | C4: % | D4: Commentaire / Action
A5: Lignes importees (total) | B5: =SUM(Data_Clean!AG2:AG1000) -> 1 | D5: Nombre total d'enquetes valides dans Raw_Data
A6: Doublons detectes (code menage + localite + date) | B6: =SUM(Data_Clean!AE2:AE1000) -> 0 | C6: =IFERROR(B6/B5,"") -> 0 | D6: Filtrer Data_Clean, colonne 'is_duplicate' = 1 pour les identifier
A7: Lignes avec champs cles manquants | B7: =SUM(Data_Clean!AF2:AF1000) -> 0 | C7: =IFERROR(B7/B5,"") -> 0 | D7: Champs cles: zone, secteur, sexe, age, satisfaction globale
A8: Ages incoherents (<0 ou >120 ans) | B8: =SUMPRODUCT((Data_Clean!H2:H1000<>"")*((Data_Clean!H2:H1000<0)+(Data_Clean!H2:H1000>120))) -> 1 | C8: =IFERROR(B8/B5,"") -> 1 | D8: A verifier manuellement dans Raw_Data
A9: Duree d'entretien anormale (fin avant debut) | B9: =SUMPRODUCT((Raw_Data!D5:D1003<>"")*(Raw_Data!E5:E1003<>"")*(Raw_Data!E5:E1003<Raw_Data!D5:D1003)) -> 0 | C9: =IFERROR(B9/B5,"") -> 0 | D9: Probleme d'horodatage cote collecte (Kobo)
A10: Enquetes sans identifiant unique (uuid) | B10: =SUMPRODUCT((Data_Clean!A2:A1000<>"")*(Data_Clean!AC2:AC1000="")) -> 0 | C10: =IFERROR(B10/B5,"") -> 0 | D10: uuid manquant : verifier la synchronisation Kobo -> n8n -> Sheets
A11: Score qualite globale des donnees | B11: =IFERROR(1-((B6+B7+B8+B9+B10)/(B5*5)),"") -> 0.8 | D11: 1 - (somme des anomalies / (lignes x 5 controles)). Plus proche de 100%, meilleure est la qualite.
A14: Comment consulter le detail des anomalies :
A15: Ouvrez l'onglet Data_Clean, activez le filtre automatique et filtrez la colonne concernee (is_duplicate=1, missing_fields_flag=1, etc.).

Sheet Indicateurs
A1: INDICATEURS CLES PDM
A3: FILTRES
A4: Zone | B4: Tous
A5: Secteur | B5: Tous
A6: Sexe | B6: Tous
A7: Periode : du | C7: (laisser vide = pas de filtre de date)
A8: au
A10: Indicateur | B10: Valeur | C10: Base (n) | E10: Definition
A11: Taille de l'echantillon analyse | B11: =SUMPRODUCT(((Indicateurs!$B$4="Tous")+(Data_Clean!C2:C1000=Indicateurs!$B$4)>0)*((Indicateurs!$B$5="Tous")+(Data_Clean!D2:D1000=Indicateurs!$B$5)>0)*((Indicateurs!$B$6="Tous")+(Data_Clean!G2:G1000=Indicateurs!$B$6)>0)*((Indicateurs!$B$7="")+(Data_Clean!B2:B1000>=Indicateurs!$B$7)>0)*((Indicateurs!$B$8="")+(Data_Clean!B2:B1000<=Indicateurs!$B$8)>0)*(Data_Clean!AG2:AG1000=1)) -> 1 | E11: Nombre d'enquetes valides correspondant aux filtres selectionnes
A12: Score de satisfaction moyen (/5) | B12: =IFERROR(SUMPRODUCT(((Indicateurs!$B$4="Tous")+(Data_Clean!C2:C1000=Indicateurs!$B$4)>0)*((Indicateurs!$B$5="Tous")+(Data_Clean!D2:D1000=Indicateurs!$B$5)>0)*((Indicateurs!$B$6="Tous")+(Data_Clean!G2:G1000=Indicateurs!$B$6)>0)*((Indicateurs!$B$7="")+(Data_Clean!B2:B1000>=Indicateurs!$B$7)>0)*((Indicateurs!$B$8="")+(Data_Clean!B2:B1000<=Indicateurs!$B$8)>0)*(Data_Clean!AG2:AG1000=1)*IF(Data_Clean!O2:O1000="",0,Data_Clean!O2:O1000))/SUMPRODUCT(((Indicateurs!$B$4="Tous")+(Data_Clean!C2:C1000=Indicateurs!$B$4)>0)*((Indicateurs!$B$5="Tous")+(Data_Clean!D2:D1000=Indicateurs!$B$5)>0)*((Indicateurs!$B$6="Tous")+(Data_Clean!G2:G1000=Indicateurs!$B$6)>0)*((Indicateurs!$B$7="")+(Data_Clean!B2:B1000>=Indicateurs!$B$7)>0)*((Indicateurs!$B$8="")+(Data_Clean!B2:B1000<=Indicateurs!$B$8)>0)*(Data_Clean!AG2:AG1000=1)*(Data_Clean!O2:O1000<>"")),"") -> 0 | C12: =SUMPRODUCT(((Indicateurs!$B$4="Tous")+(Data_Clean!C2:C1000=Indicateurs!$B$4)>0)*((Indicateurs!$B$5="Tous")+(Data_Clean!D2:D1000=Indicateurs!$B$5)>0)*((Indicateurs!$B$6="Tous")+(Data_Clean!G2:G1000=Indicateurs!$B$6)>0)*((Indicateurs!$B$7="")+(Data_Clean!B2:B1000>=Indicateurs!$B$7)>0)*((Indicateurs!$B$8="")+(Data_Clean!B2:B1000<=Indicateurs!$B$8)>0)*(Data_Clean!AG2:AG1000=1)*(Data_Clean!O2:O1000<>"")) -> 1 | E12: 1=tres insatisfait a 5=tres satisfait
A13: Taux de satisfaction (score >= seuil Config) | B13: =IFERROR(SUMPRODUCT(((Indicateurs!$B$4="Tous")+(Data_Clean!C2:C1000=Indicateurs!$B$4)>0)*((Indicateurs!$B$5="Tous")+(Data_Clean!D2:D1000=Indicateurs!$B$5)>0)*((Indicateurs!$B$6="Tous")+(Data_Clean!G2:G1000=Indicateurs!$B$6)>0)*((Indicateurs!$B$7="")+(Data_Clean!B2:B1000>=Indicateurs!$B$7)>0)*((Indicateurs!$B$8="")+(Data_Clean!B2:B1000<=Indicateurs!$B$8)>0)*(Data_Clean!AG2:AG1000=1)*IF(Data_Clean!O2:O1000="",0,--(Data_Clean!O2:O1000>=Config!$B$5)))/SUMPRODUCT(((Indicateurs!$B$4="Tous")+(Data_Clean!C2:C1000=Indicateurs!$B$4)>0)*((Indicateurs!$B$5="Tous")+(Data_Clean!D2:D1000=Indicateurs!$B$5)>0)*((Indicateurs!$B$6="Tous")+(Data_Clean!G2:G1000=Indicateurs!$B$6)>0)*((Indicateurs!$B$7="")+(Data_Clean!B2:B1000>=Indicateurs!$B$7)>0)*((Indicateurs!$B$8="")+(Data_Clean!B2:B1000<=Indicateurs!$B$8)>0)*(Data_Clean!AG2:AG1000=1)*(Data_Clean!O2:O1000<>"")),"") -> 0 | C13: =SUMPRODUCT(((Indicateurs!$B$4="Tous")+(Data_Clean!C2:C1000=Indicateurs!$B$4)>0)*((Indicateurs!$B$5="Tous")+(Data_Clean!D2:D1000=Indicateurs!$B$5)>0)*((Indicateurs!$B$6="Tous")+(Data_Clean!G2:G1000=Indicateurs!$B$6)>0)*((Indicateurs!$B$7="")+(Data_Clean!B2:B1000>=Indicateurs!$B$7)>0)*((Indicateurs!$B$8="")+(Data_Clean!B2:B1000<=Indicateurs!$B$8)>0)*(Data_Clean!AG2:AG1000=1)*(Data_Clean!O2:O1000<>"")) -> 1 | E13: % de repondants avec score de satisfaction superieur ou egal au seuil defini dans Config
A14: Taux d'utilisation des biens/services distribues | B14: =IFERROR(SUMPRODUCT(((Indicateurs!$B$4="Tous")+(Data_Clean!C2:C1000=Indicateurs!$B$4)>0)*((Indicateurs!$B$5="Tous")+(Data_Clean!D2:D1000=Indicateurs!$B$5)>0)*((Indicateurs!$B$6="Tous")+(Data_Clean!G2:G1000=Indicateurs!$B$6)>0)*((Indicateurs!$B$7="")+(Data_Clean!B2:B1000>=Indicateurs!$B$7)>0)*((Indicateurs!$B$8="")+(Data_Clean!B2:B1000<=Indicateurs!$B$8)>0)*(Data_Clean!AG2:AG1000=1)*IF(Data_Clean!Q2:Q1000="",0,Data_Clean!Q2:Q1000))/SUMPRODUCT(((Indicateurs!$B$4="Tous")+(Data_Clean!C2:C1000=Indicateurs!$B$4)>0)*((Indicateurs!$B$5="Tous")+(Data_Clean!D2:D1000=Indicateurs!$B$5)>0)*((Indicateurs!$B$6="Tous")+(Data_Clean!G2:G1000=Indicateurs!$B$6)>0)*((Indicateurs!$B$7="")+(Data_Clean!B2:B1000>=Indicateurs!$B$7)>0)*((Indicateurs!$B$8="")+(Data_Clean!B2:B1000<=Indicateurs!$B$8)>0)*(Data_Clean!AG2:AG1000=1)*(Data_Clean!Q2:Q1000<>"")),"") -> 1 | C14: =SUMPRODUCT(((Indicateurs!$B$4="Tous")+(Data_Clean!C2:C1000=Indicateurs!$B$4)>0)*((Indicateurs!$B$5="Tous")+(Data_Clean!D2:D1000=Indicateurs!$B$5)>0)*((Indicateurs!$B$6="Tous")+(Data_Clean!G2:G1000=Indicateurs!$B$6)>0)*((Indicateurs!$B$7="")+(Data_Clean!B2:B1000>=Indicateurs!$B$7)>0)*((Indicateurs!$B$8="")+(Data_Clean!B2:B1000<=Indicateurs!$B$8)>0)*(Data_Clean!AG2:AG1000=1)*(Data_Clean!Q2:Q1000<>"")) -> 1 | E14: % de menages ayant utilise le bien/service comme prevu
A15: Adequation aux besoins | B15: =IFERROR(SUMPRODUCT(((Indicateurs!$B$4="Tous")+(Data_Clean!C2:C1000=Indicateurs!$B$4)>0)*((Indicateurs!$B$5="Tous")+(Data_Clean!D2:D1000=Indicateurs!$B$5)>0)*((Indicateurs!$B$6="Tous")+(Data_Clean!G2:G1000=Indicateurs!$B$6)>0)*((Indicateurs!$B$7="")+(Data_Clean!B2:B1000>=Indicateurs!$B$7)>0)*((Indicateurs!$B$8="")+(Data_Clean!B2:B1000<=Indicateurs!$B$8)>0)*(Data_Clean!AG2:AG1000=1)*IF(Data_Clean!AB2:AB1000="",0,Data_Clean!AB2:AB1000))/SUMPRODUCT(((Indicateurs!$B$4="Tous")+(Data_Clean!C2:C1000=Indicateurs!$B$4)>0)*((Indicateurs!$B$5="Tous")+(Data_Clean!D2:D1000=Indicateurs!$B$5)>0)*((Indicateurs!$B$6="Tous")+(Data_Clean!G2:G1000=Indicateurs!$B$6)>0)*((Indicateurs!$B$7="")+(Data_Clean!B2:B1000>=Indicateurs!$B$7)>0)*((Indicateurs!$B$8="")+(Data_Clean!B2:B1000<=Indicateurs!$B$8)>0)*(Data_Clean!AG2:AG1000=1)*(Data_Clean!AB2:AB1000<>"")),"") -> 0 | C15: =SUMPRODUCT(((Indicateurs!$B$4="Tous")+(Data_Clean!C2:C1000=Indicateurs!$B$4)>0)*((Indicateurs!$B$5="Tous")+(Data_Clean!D2:D1000=Indicateurs!$B$5)>0)*((Indicateurs!$B$6="Tous")+(Data_Clean!G2:G1000=Indicateurs!$B$6)>0)*((Indicateurs!$B$7="")+(Data_Clean!B2:B1000>=Indicateurs!$B$7)>0)*((Indicateurs!$B$8="")+(Data_Clean!B2:B1000<=Indicateurs!$B$8)>0)*(Data_Clean!AG2:AG1000=1)*(Data_Clean!AB2:AB1000<>"")) -> 1 | E15: % jugeant l'assistance adaptee a leurs besoins
A16: Connaissance du mecanisme de feedback/plainte | B16: =IFERROR(SUMPRODUCT(((Indicateurs!$B$4="Tous")+(Data_Clean!C2:C1000=Indicateurs!$B$4)>0)*((Indicateurs!$B$5="Tous")+(Data_Clean!D2:D1000=Indicateurs!$B$5)>0)*((Indicateurs!$B$6="Tous")+(Data_Clean!G2:G1000=Indicateurs!$B$6)>0)*((Indicateurs!$B$7="")+(Data_Clean!B2:B1000>=Indicateurs!$B$7)>0)*((Indicateurs!$B$8="")+(Data_Clean!B2:B1000<=Indicateurs!$B$8)>0)*(Data_Clean!AG2:AG1000=1)*IF(Data_Clean!S2:S1000="",0,Data_Clean!S2:S1000))/SUMPRODUCT(((Indicateurs!$B$4="Tous")+(Data_Clean!C2:C1000=Indicateurs!$B$4)>0)*((Indicateurs!$B$5="Tous")+(Data_Clean!D2:D1000=Indicateurs!$B$5)>0)*((Indicateurs!$B$6="Tous")+(Data_Clean!G2:G1000=Indicateurs!$B$6)>0)*((Indicateurs!$B$7="")+(Data_Clean!B2:B1000>=Indicateurs!$B$7)>0)*((Indicateurs!$B$8="")+(Data_Clean!B2:B1000<=Indicateurs!$B$8)>0)*(Data_Clean!AG2:AG1000=1)*(Data_Clean!S2:S1000<>"")),"") -> 0 | C16: =SUMPRODUCT(((Indicateurs!$B$4="Tous")+(Data_Clean!C2:C1000=Indicateurs!$B$4)>0)*((Indicateurs!$B$5="Tous")+(Data_Clean!D2:D1000=Indicateurs!$B$5)>0)*((Indicateurs!$B$6="Tous")+(Data_Clean!G2:G1000=Indicateurs!$B$6)>0)*((Indicateurs!$B$7="")+(Data_Clean!B2:B1000>=Indicateurs!$B$7)>0)*((Indicateurs!$B$8="")+(Data_Clean!B2:B1000<=Indicateurs!$B$8)>0)*(Data_Clean!AG2:AG1000=1)*(Data_Clean!S2:S1000<>"")) -> 1 | E16: % connaissant le mecanisme de redevabilite (redevabilite)
A17: Utilisation du mecanisme de feedback/plainte | B17: =IFERROR(SUMPRODUCT(((Indicateurs!$B$4="Tous")+(Data_Clean!C2:C1000=Indicateurs!$B$4)>0)*((Indicateurs!$B$5="Tous")+(Data_Clean!D2:D1000=Indicateurs!$B$5)>0)*((Indicateurs!$B$6="Tous")+(Data_Clean!G2:G1000=Indicateurs!$B$6)>0)*((Indicateurs!$B$7="")+(Data_Clean!B2:B1000>=Indicateurs!$B$7)>0)*((Indicateurs!$B$8="")+(Data_Clean!B2:B1000<=Indicateurs!$B$8)>0)*(Data_Clean!AG2:AG1000=1)*IF(Data_Clean!U2:U1000="",0,Data_Clean!U2:U1000))/SUMPRODUCT(((Indicateurs!$B$4="Tous")+(Data_Clean!C2:C1000=Indicateurs!$B$4)>0)*((Indicateurs!$B$5="Tous")+(Data_Clean!D2:D1000=Indicateurs!$B$5)>0)*((Indicateurs!$B$6="Tous")+(Data_Clean!G2:G1000=Indicateurs!$B$6)>0)*((Indicateurs!$B$7="")+(Data_Clean!B2:B1000>=Indicateurs!$B$7)>0)*((Indicateurs!$B$8="")+(Data_Clean!B2:B1000<=Indicateurs!$B$8)>0)*(Data_Clean!AG2:AG1000=1)*(Data_Clean!U2:U1000<>"")),"") -> 0 | C17: =SUMPRODUCT(((Indicateurs!$B$4="Tous")+(Data_Clean!C2:C1000=Indicateurs!$B$4)>0)*((Indicateurs!$B$5="Tous")+(Data_Clean!D2:D1000=Indicateurs!$B$5)>0)*((Indicateurs!$B$6="Tous")+(Data_Clean!G2:G1000=Indicateurs!$B$6)>0)*((Indicateurs!$B$7="")+(Data_Clean!B2:B1000>=Indicateurs!$B$7)>0)*((Indicateurs!$B$8="")+(Data_Clean!B2:B1000<=Indicateurs!$B$8)>0)*(Data_Clean!AG2:AG1000=1)*(Data_Clean!U2:U1000<>"")) -> 1 | E17: % ayant deja utilise le mecanisme de feedback
A18: Acces equitable a l'assistance | B18: =IFERROR(SUMPRODUCT(((Indicateurs!$B$4="Tous")+(Data_Clean!C2:C1000=Indicateurs!$B$4)>0)*((Indicateurs!$B$5="Tous")+(Data_Clean!D2:D1000=Indicateurs!$B$5)>0)*((Indicateurs!$B$6="Tous")+(Data_Clean!G2:G1000=Indicateurs!$B$6)>0)*((Indicateurs!$B$7="")+(Data_Clean!B2:B1000>=Indicateurs!$B$7)>0)*((Indicateurs!$B$8="")+(Data_Clean!B2:B1000<=Indicateurs!$B$8)>0)*(Data_Clean!AG2:AG1000=1)*IF(Data_Clean!V2:V1000="",0,Data_Clean!V2:V1000))/SUMPRODUCT(((Indicateurs!$B$4="Tous")+(Data_Clean!C2:C1000=Indicateurs!$B$4)>0)*((Indicateurs!$B$5="Tous")+(Data_Clean!D2:D1000=Indicateurs!$B$5)>0)*((Indicateurs!$B$6="Tous")+(Data_Clean!G2:G1000=Indicateurs!$B$6)>0)*((Indicateurs!$B$7="")+(Data_Clean!B2:B1000>=Indicateurs!$B$7)>0)*((Indicateurs!$B$8="")+(Data_Clean!B2:B1000<=Indicateurs!$B$8)>0)*(Data_Clean!AG2:AG1000=1)*(Data_Clean!V2:V1000<>"")),"") -> 0 | C18: =SUMPRODUCT(((Indicateurs!$B$4="Tous")+(Data_Clean!C2:C1000=Indicateurs!$B$4)>0)*((Indicateurs!$B$5="Tous")+(Data_Clean!D2:D1000=Indicateurs!$B$5)>0)*((Indicateurs!$B$6="Tous")+(Data_Clean!G2:G1000=Indicateurs!$B$6)>0)*((Indicateurs!$B$7="")+(Data_Clean!B2:B1000>=Indicateurs!$B$7)>0)*((Indicateurs!$B$8="")+(Data_Clean!B2:B1000<=Indicateurs!$B$8)>0)*(Data_Clean!AG2:AG1000=1)*(Data_Clean!V2:V1000<>"")) -> 1 | E18: % jugeant l'acces a l'assistance equitable (protection/inclusion)
A19: Securite lors de la distribution | B19: =IFERROR(SUMPRODUCT(((Indicateurs!$B$4="Tous")+(Data_Clean!C2:C1000=Indicateurs!$B$4)>0)*((Indicateurs!$B$5="Tous")+(Data_Clean!D2:D1000=Indicateurs!$B$5)>0)*((Indicateurs!$B$6="Tous")+(Data_Clean!G2:G1000=Indicateurs!$B$6)>0)*((Indicateurs!$B$7="")+(Data_Clean!B2:B1000>=Indicateurs!$B$7)>0)*((Indicateurs!$B$8="")+(Data_Clean!B2:B1000<=Indicateurs!$B$8)>0)*(Data_Clean!AG2:AG1000=1)*IF(Data_Clean!W2:W1000="",0,Data_Clean!W2:W1000))/SUMPRODUCT(((Indicateurs!$B$4="Tous")+(Data_Clean!C2:C1000=Indicateurs!$B$4)>0)*((Indicateurs!$B$5="Tous")+(Data_Clean!D2:D1000=Indicateurs!$B$5)>0)*((Indicateurs!$B$6="Tous")+(Data_Clean!G2:G1000=Indicateurs!$B$6)>0)*((Indicateurs!$B$7="")+(Data_Clean!B2:B1000>=Indicateurs!$B$7)>0)*((Indicateurs!$B$8="")+(Data_Clean!B2:B1000<=Indicateurs!$B$8)>0)*(Data_Clean!AG2:AG1000=1)*(Data_Clean!W2:W1000<>"")),"") -> 0 | C19: =SUMPRODUCT(((Indicateurs!$B$4="Tous")+(Data_Clean!C2:C1000=Indicateurs!$B$4)>0)*((Indicateurs!$B$5="Tous")+(Data_Clean!D2:D1000=Indicateurs!$B$5)>0)*((Indicateurs!$B$6="Tous")+(Data_Clean!G2:G1000=Indicateurs!$B$6)>0)*((Indicateurs!$B$7="")+(Data_Clean!B2:B1000>=Indicateurs!$B$7)>0)*((Indicateurs!$B$8="")+(Data_Clean!B2:B1000<=Indicateurs!$B$8)>0)*(Data_Clean!AG2:AG1000=1)*(Data_Clean!W2:W1000<>"")) -> 1 | E19: % se sentant en securite lors de la distribution
A20: Priorite accordee aux plus vulnerables | B20: =IFERROR(SUMPRODUCT(((Indicateurs!$B$4="Tous")+(Data_Clean!C2:C1000=Indicateurs!$B$4)>0)*((Indicateurs!$B$5="Tous")+(Data_Clean!D2:D1000=Indicateurs!$B$5)>0)*((Indicateurs!$B$6="Tous")+(Data_Clean!G2:G1000=Indicateurs!$B$6)>0)*((Indicateurs!$B$7="")+(Data_Clean!B2:B1000>=Indicateurs!$B$7)>0)*((Indicateurs!$B$8="")+(Data_Clean!B2:B1000<=Indicateurs!$B$8)>0)*(Data_Clean!AG2:AG1000=1)*IF(Data_Clean!X2:X1000="",0,Data_Clean!X2:X1000))/SUMPRODUCT(((Indicateurs!$B$4="Tous")+(Data_Clean!C2:C1000=Indicateurs!$B$4)>0)*((Indicateurs!$B$5="Tous")+(Data_Clean!D2:D1000=Indicateurs!$B$5)>0)*((Indicateurs!$B$6="Tous")+(Data_Clean!G2:G1000=Indicateurs!$B$6)>0)*((Indicateurs!$B$7="")+(Data_Clean!B2:B1000>=Indicateurs!$B$7)>0)*((Indicateurs!$B$8="")+(Data_Clean!B2:B1000<=Indicateurs!$B$8)>0)*(Data_Clean!AG2:AG1000=1)*(Data_Clean!X2:X1000<>"")),"") -> 0 | C20: =SUMPRODUCT(((Indicateurs!$B$4="Tous")+(Data_Clean!C2:C1000=Indicateurs!$B$4)>0)*((Indicateurs!$B$5="Tous")+(Data_Clean!D2:D1000=Indicateurs!$B$5)>0)*((Indicateurs!$B$6="Tous")+(Data_Clean!G2:G1000=Indicateurs!$B$6)>0)*((Indicateurs!$B$7="")+(Data_Clean!B2:B1000>=Indicateurs!$B$7)>0)*((Indicateurs!$B$8="")+(Data_Clean!B2:B1000<=Indicateurs!$B$8)>0)*(Data_Clean!AG2:AG1000=1)*(Data_Clean!X2:X1000<>"")) -> 1 | E20: % estimant que les plus vulnerables ont ete prioritaires
A21: Dignite du traitement recu | B21: =IFERROR(SUMPRODUCT(((Indicateurs!$B$4="Tous")+(Data_Clean!C2:C1000=Indicateurs!$B$4)>0)*((Indicateurs!$B$5="Tous")+(Data_Clean!D2:D1000=Indicateurs!$B$5)>0)*((Indicateurs!$B$6="Tous")+(Data_Clean!G2:G1000=Indicateurs!$B$6)>0)*((Indicateurs!$B$7="")+(Data_Clean!B2:B1000>=Indicateurs!$B$7)>0)*((Indicateurs!$B$8="")+(Data_Clean!B2:B1000<=Indicateurs!$B$8)>0)*(Data_Clean!AG2:AG1000=1)*IF(Data_Clean!Y2:Y1000="",0,Data_Clean!Y2:Y1000))/SUMPRODUCT(((Indicateurs!$B$4="Tous")+(Data_Clean!C2:C1000=Indicateurs!$B$4)>0)*((Indicateurs!$B$5="Tous")+(Data_Clean!D2:D1000=Indicateurs!$B$5)>0)*((Indicateurs!$B$6="Tous")+(Data_Clean!G2:G1000=Indicateurs!$B$6)>0)*((Indicateurs!$B$7="")+(Data_Clean!B2:B1000>=Indicateurs!$B$7)>0)*((Indicateurs!$B$8="")+(Data_Clean!B2:B1000<=Indicateurs!$B$8)>0)*(Data_Clean!AG2:AG1000=1)*(Data_Clean!Y2:Y1000<>"")),"") -> 0 | C21: =SUMPRODUCT(((Indicateurs!$B$4="Tous")+(Data_Clean!C2:C1000=Indicateurs!$B$4)>0)*((Indicateurs!$B$5="Tous")+(Data_Clean!D2:D1000=Indicateurs!$B$5)>0)*((Indicateurs!$B$6="Tous")+(Data_Clean!G2:G1000=Indicateurs!$B$6)>0)*((Indicateurs!$B$7="")+(Data_Clean!B2:B1000>=Indicateurs!$B$7)>0)*((Indicateurs!$B$8="")+(Data_Clean!B2:B1000<=Indicateurs!$B$8)>0)*(Data_Clean!AG2:AG1000=1)*(Data_Clean!Y2:Y1000<>"")) -> 1 | E21: % ayant ete traite avec dignite et respect
A22: Recommanderait l'assistance / le programme | B22: =IFERROR(SUMPRODUCT(((Indicateurs!$B$4="Tous")+(Data_Clean!C2:C1000=Indicateurs!$B$4)>0)*((Indicateurs!$B$5="Tous")+(Data_Clean!D2:D1000=Indicateurs!$B$5)>0)*((Indicateurs!$B$6="Tous")+(Data_Clean!G2:G1000=Indicateurs!$B$6)>0)*((Indicateurs!$B$7="")+(Data_Clean!B2:B1000>=Indicateurs!$B$7)>0)*((Indicateurs!$B$8="")+(Data_Clean!B2:B1000<=Indicateurs!$B$8)>0)*(Data_Clean!AG2:AG1000=1)*IF(Data_Clean!Z2:Z1000="",0,Data_Clean!Z2:Z1000))/SUMPRODUCT(((Indicateurs!$B$4="Tous")+(Data_Clean!C2:C1000=Indicateurs!$B$4)>0)*((Indicateurs!$B$5="Tous")+(Data_Clean!D2:D1000=Indicateurs!$B$5)>0)*((Indicateurs!$B$6="Tous")+(Data_Clean!G2:G1000=Indicateurs!$B$6)>0)*((Indicateurs!$B$7="")+(Data_Clean!B2:B1000>=Indicateurs!$B$7)>0)*((Indicateurs!$B$8="")+(Data_Clean!B2:B1000<=Indicateurs!$B$8)>0)*(Data_Clean!AG2:AG1000=1)*(Data_Clean!Z2:Z1000<>"")),"") -> 0 | C22: =SUMPRODUCT(((Indicateurs!$B$4="Tous")+(Data_Clean!C2:C1000=Indicateurs!$B$4)>0)*((Indicateurs!$B$5="Tous")+(Data_Clean!D2:D1000=Indicateurs!$B$5)>0)*((Indicateurs!$B$6="Tous")+(Data_Clean!G2:G1000=Indicateurs!$B$6)>0)*((Indicateurs!$B$7="")+(Data_Clean!B2:B1000>=Indicateurs!$B$7)>0)*((Indicateurs!$B$8="")+(Data_Clean!B2:B1000<=Indicateurs!$B$8)>0)*(Data_Clean!AG2:AG1000=1)*(Data_Clean!Z2:Z1000<>"")) -> 1 | E22: % recommanderait le programme a d'autres
A23: Information disponible sur l'assistance | B23: =IFERROR(SUMPRODUCT(((Indicateurs!$B$4="Tous")+(Data_Clean!C2:C1000=Indicateurs!$B$4)>0)*((Indicateurs!$B$5="Tous")+(Data_Clean!D2:D1000=Indicateurs!$B$5)>0)*((Indicateurs!$B$6="Tous")+(Data_Clean!G2:G1000=Indicateurs!$B$6)>0)*((Indicateurs!$B$7="")+(Data_Clean!B2:B1000>=Indicateurs!$B$7)>0)*((Indicateurs!$B$8="")+(Data_Clean!B2:B1000<=Indicateurs!$B$8)>0)*(Data_Clean!AG2:AG1000=1)*IF(Data_Clean!AA2:AA1000="",0,Data_Clean!AA2:AA1000))/SUMPRODUCT(((Indicateurs!$B$4="Tous")+(Data_Clean!C2:C1000=Indicateurs!$B$4)>0)*((Indicateurs!$B$5="Tous")+(Data_Clean!D2:D1000=Indicateurs!$B$5)>0)*((Indicateurs!$B$6="Tous")+(Data_Clean!G2:G1000=Indicateurs!$B$6)>0)*((Indicateurs!$B$7="")+(Data_Clean!B2:B1000>=Indicateurs!$B$7)>0)*((Indicateurs!$B$8="")+(Data_Clean!B2:B1000<=Indicateurs!$B$8)>0)*(Data_Clean!AG2:AG1000=1)*(Data_Clean!AA2:AA1000<>"")),"") -> 0 | C23: =SUMPRODUCT(((Indicateurs!$B$4="Tous")+(Data_Clean!C2:C1000=Indicateurs!$B$4)>0)*((Indicateurs!$B$5="Tous")+(Data_Clean!D2:D1000=Indicateurs!$B$5)>0)*((Indicateurs!$B$6="Tous")+(Data_Clean!G2:G1000=Indicateurs!$B$6)>0)*((Indicateurs!$B$7="")+(Data_Clean!B2:B1000>=Indicateurs!$B$7)>0)*((Indicateurs!$B$8="")+(Data_Clean!B2:B1000<=Indicateurs!$B$8)>0)*(Data_Clean!AG2:AG1000=1)*(Data_Clean!AA2:AA1000<>"")) -> 1 | E23: % jugeant l'information sur l'assistance suffisamment disponible
A24: Part de menages vulnerables dans l'echantillon | B24: =IFERROR(SUMPRODUCT(((Indicateurs!$B$4="Tous")+(Data_Clean!C2:C1000=Indicateurs!$B$4)>0)*((Indicateurs!$B$5="Tous")+(Data_Clean!D2:D1000=Indicateurs!$B$5)>0)*((Indicateurs!$B$6="Tous")+(Data_Clean!G2:G1000=Indicateurs!$B$6)>0)*((Indicateurs!$B$7="")+(Data_Clean!B2:B1000>=Indicateurs!$B$7)>0)*((Indicateurs!$B$8="")+(Data_Clean!B2:B1000<=Indicateurs!$B$8)>0)*(Data_Clean!AG2:AG1000=1)*IF(Data_Clean!L2:L1000="",0,Data_Clean!L2:L1000))/SUMPRODUCT(((Indicateurs!$B$4="Tous")+(Data_Clean!C2:C1000=Indicateurs!$B$4)>0)*((Indicateurs!$B$5="Tous")+(Data_Clean!D2:D1000=Indicateurs!$B$5)>0)*((Indicateurs!$B$6="Tous")+(Data_Clean!G2:G1000=Indicateurs!$B$6)>0)*((Indicateurs!$B$7="")+(Data_Clean!B2:B1000>=Indicateurs!$B$7)>0)*((Indicateurs!$B$8="")+(Data_Clean!B2:B1000<=Indicateurs!$B$8)>0)*(Data_Clean!AG2:AG1000=1)),"") -> 1 | C24: =SUMPRODUCT(((Indicateurs!$B$4="Tous")+(Data_Clean!C2:C1000=Indicateurs!$B$4)>0)*((Indicateurs!$B$5="Tous")+(Data_Clean!D2:D1000=Indicateurs!$B$5)>0)*((Indicateurs!$B$6="Tous")+(Data_Clean!G2:G1000=Indicateurs!$B$6)>0)*((Indicateurs!$B$7="")+(Data_Clean!B2:B1000>=Indicateurs!$B$7)>0)*((Indicateurs!$B$8="")+(Data_Clean!B2:B1000<=Indicateurs!$B$8)>0)*(Data_Clean!AG2:AG1000=1)) -> 1 | E24: % de repondants signalant une situation de vulnerabilite

Sheet Desagregation
A1: DESAGREGATION DES RESULTATS
A2: Respecte les filtres definis dans l'onglet Indicateurs (sauf la dimension analysee elle-meme)
A4: PAR SEXE
A5: Categorie | B5: n | C5: % echantillon | D5: Score satisf. moyen (/5) | E5: % utilisation du bien
A6: feminin | B6: =SUMPRODUCT(((Indicateurs!$B$4="Tous")+(Data_Clean!C2:C1000=Indicateurs!$B$4)>0)*((Indicateurs!$B$5="Tous")+(Data_Clean!D2:D1000=Indicateurs!$B$5)>0)*((Indicateurs!$B$7="")+(Data_Clean!B2:B1000>=Indicateurs!$B$7)>0)*((Indicateurs!$B$8="")+(Data_Clean!B2:B1000<=Indicateurs!$B$8)>0)*(Data_Clean!AG2:AG1000=1)*(Data_Clean!G2:G1000="feminin")) -> 0 | C6: =IFERROR(B6/SUMPRODUCT(((Indicateurs!$B$4="Tous")+(Data_Clean!C2:C1000=Indicateurs!$B$4)>0)*((Indicateurs!$B$5="Tous")+(Data_Clean!D2:D1000=Indicateurs!$B$5)>0)*((Indicateurs!$B$7="")+(Data_Clean!B2:B1000>=Indicateurs!$B$7)>0)*((Indicateurs!$B$8="")+(Data_Clean!B2:B1000<=Indicateurs!$B$8)>0)*(Data_Clean!AG2:AG1000=1)),"") -> 0 | D6: =IFERROR(SUMPRODUCT(((Indicateurs!$B$4="Tous")+(Data_Clean!C2:C1000=Indicateurs!$B$4)>0)*((Indicateurs!$B$5="Tous")+(Data_Clean!D2:D1000=Indicateurs!$B$5)>0)*((Indicateurs!$B$7="")+(Data_Clean!B2:B1000>=Indicateurs!$B$7)>0)*((Indicateurs!$B$8="")+(Data_Clean!B2:B1000<=Indicateurs!$B$8)>0)*(Data_Clean!AG2:AG1000=1)*(Data_Clean!G2:G1000="feminin")*IF(Data_Clean!O2:O1000="",0,Data_Clean!O2:O1000))/SUMPRODUCT(((Indicateurs!$B$4="Tous")+(Data_Clean!C2:C1000=Indicateurs!$B$4)>0)*((Indicateurs!$B$5="Tous")+(Data_Clean!D2:D1000=Indicateurs!$B$5)>0)*((Indicateurs!$B$7="")+(Data_Clean!B2:B1000>=Indicateurs!$B$7)>0)*((Indicateurs!$B$8="")+(Data_Clean!B2:B1000<=Indicateurs!$B$8)>0)*(Data_Clean!AG2:AG1000=1)*(Data_Clean!G2:G1000="feminin")*(Data_Clean!O2:O1000<>"")),"") | E6: =IFERROR(SUMPRODUCT(((Indicateurs!$B$4="Tous")+(Data_Clean!C2:C1000=Indicateurs!$B$4)>0)*((Indicateurs!$B$5="Tous")+(Data_Clean!D2:D1000=Indicateurs!$B$5)>0)*((Indicateurs!$B$7="")+(Data_Clean!B2:B1000>=Indicateurs!$B$7)>0)*((Indicateurs!$B$8="")+(Data_Clean!B2:B1000<=Indicateurs!$B$8)>0)*(Data_Clean!AG2:AG1000=1)*(Data_Clean!G2:G1000="feminin")*IF(Data_Clean!Q2:Q1000="",0,Data_Clean!Q2:Q1000))/SUMPRODUCT(((Indicateurs!$B$4="Tous")+(Data_Clean!C2:C1000=Indicateurs!$B$4)>0)*((Indicateurs!$B$5="Tous")+(Data_Clean!D2:D1000=Indicateurs!$B$5)>0)*((Indicateurs!$B$7="")+(Data_Clean!B2:B1000>=Indicateurs!$B$7)>0)*((Indicateurs!$B$8="")+(Data_Clean!B2:B1000<=Indicateurs!$B$8)>0)*(Data_Clean!AG2:AG1000=1)*(Data_Clean!G2:G1000="feminin")*(Data_Clean!Q2:Q1000<>"")),"")
A7: masculin | B7: =SUMPRODUCT(((Indicateurs!$B$4="Tous")+(Data_Clean!C2:C1000=Indicateurs!$B$4)>0)*((Indicateurs!$B$5="Tous")+(Data_Clean!D2:D1000=Indicateurs!$B$5)>0)*((Indicateurs!$B$7="")+(Data_Clean!B2:B1000>=Indicateurs!$B$7)>0)*((Indicateurs!$B$8="")+(Data_Clean!B2:B1000<=Indicateurs!$B$8)>0)*(Data_Clean!AG2:AG1000=1)*(Data_Clean!G2:G1000="masculin")) -> 0 | C7: =IFERROR(B7/SUMPRODUCT(((Indicateurs!$B$4="Tous")+(Data_Clean!C2:C1000=Indicateurs!$B$4)>0)*((Indicateurs!$B$5="Tous")+(Data_Clean!D2:D1000=Indicateurs!$B$5)>0)*((Indicateurs!$B$7="")+(Data_Clean!B2:B1000>=Indicateurs!$B$7)>0)*((Indicateurs!$B$8="")+(Data_Clean!B2:B1000<=Indicateurs!$B$8)>0)*(Data_Clean!AG2:AG1000=1)),"") -> 0 | D7: =IFERROR(SUMPRODUCT(((Indicateurs!$B$4="Tous")+(Data_Clean!C2:C1000=Indicateurs!$B$4)>0)*((Indicateurs!$B$5="Tous")+(Data_Clean!D2:D1000=Indicateurs!$B$5)>0)*((Indicateurs!$B$7="")+(Data_Clean!B2:B1000>=Indicateurs!$B$7)>0)*((Indicateurs!$B$8="")+(Data_Clean!B2:B1000<=Indicateurs!$B$8)>0)*(Data_Clean!AG2:AG1000=1)*(Data_Clean!G2:G1000="masculin")*IF(Data_Clean!O2:O1000="",0,Data_Clean!O2:O1000))/SUMPRODUCT(((Indicateurs!$B$4="Tous")+(Data_Clean!C2:C1000=Indicateurs!$B$4)>0)*((Indicateurs!$B$5="Tous")+(Data_Clean!D2:D1000=Indicateurs!$B$5)>0)*((Indicateurs!$B$7="")+(Data_Clean!B2:B1000>=Indicateurs!$B$7)>0)*((Indicateurs!$B$8="")+(Data_Clean!B2:B1000<=Indicateurs!$B$8)>0)*(Data_Clean!AG2:AG1000=1)*(Data_Clean!G2:G1000="masculin")*(Data_Clean!O2:O1000<>"")),"") | E7: =IFERROR(SUMPRODUCT(((Indicateurs!$B$4="Tous")+(Data_Clean!C2:C1000=Indicateurs!$B$4)>0)*((Indicateurs!$B$5="Tous")+(Data_Clean!D2:D1000=Indicateurs!$B$5)>0)*((Indicateurs!$B$7="")+(Data_Clean!B2:B1000>=Indicateurs!$B$7)>0)*((Indicateurs!$B$8="")+(Data_Clean!B2:B1000<=Indicateurs!$B$8)>0)*(Data_Clean!AG2:AG1000=1)*(Data_Clean!G2:G1000="masculin")*IF(Data_Clean!Q2:Q1000="",0,Data_Clean!Q2:Q1000))/SUMPRODUCT(((Indicateurs!$B$4="Tous")+(Data_Clean!C2:C1000=Indicateurs!$B$4)>0)*((Indicateurs!$B$5="Tous")+(Data_Clean!D2:D1000=Indicateurs!$B$5)>0)*((Indicateurs!$B$7="")+(Data_Clean!B2:B1000>=Indicateurs!$B$7)>0)*((Indicateurs!$B$8="")+(Data_Clean!B2:B1000<=Indicateurs!$B$8)>0)*(Data_Clean!AG2:AG1000=1)*(Data_Clean!G2:G1000="masculin")*(Data_Clean!Q2:Q1000<>"")),"")
A9: PAR TRANCHE D'AGE
A10: Categorie | B10: n | C10: % echantillon | D10: Score satisf. moyen (/5) | E10: % utilisation du bien
A11: <18 ans | B11: =SUMPRODUCT(((Indicateurs!$B$4="Tous")+(Data_Clean!C2:C1000=Indicateurs!$B$4)>0)*((Indicateurs!$B$5="Tous")+(Data_Clean!D2:D1000=Indicateurs!$B$5)>0)*((Indicateurs!$B$6="Tous")+(Data_Clean!G2:G1000=Indicateurs!$B$6)>0)*((Indicateurs!$B$7="")+(Data_Clean!B2:B1000>=Indicateurs!$B$7)>0)*((Indicateurs!$B$8="")+(Data_Clean!B2:B1000<=Indicateurs!$B$8)>0)*(Data_Clean!AG2:AG1000=1)*(Data_Clean!I2:I1000="<18 ans")) -> 0 | C11: =IFERROR(B11/SUMPRODUCT(((Indicateurs!$B$4="Tous")+(Data_Clean!C2:C1000=Indicateurs!$B$4)>0)*((Indicateurs!$B$5="Tous")+(Data_Clean!D2:D1000=Indicateurs!$B$5)>0)*((Indicateurs!$B$6="Tous")+(Data_Clean!G2:G1000=Indicateurs!$B$6)>0)*((Indicateurs!$B$7="")+(Data_Clean!B2:B1000>=Indicateurs!$B$7)>0)*((Indicateurs!$B$8="")+(Data_Clean!B2:B1000<=Indicateurs!$B$8)>0)*(Data_Clean!AG2:AG1000=1)),"") -> 0 | D11: =IFERROR(SUMPRODUCT(((Indicateurs!$B$4="Tous")+(Data_Clean!C2:C1000=Indicateurs!$B$4)>0)*((Indicateurs!$B$5="Tous")+(Data_Clean!D2:D1000=Indicateurs!$B$5)>0)*((Indicateurs!$B$6="Tous")+(Data_Clean!G2:G1000=Indicateurs!$B$6)>0)*((Indicateurs!$B$7="")+(Data_Clean!B2:B1000>=Indicateurs!$B$7)>0)*((Indicateurs!$B$8="")+(Data_Clean!B2:B1000<=Indicateurs!$B$8)>0)*(Data_Clean!AG2:AG1000=1)*(Data_Clean!I2:I1000="<18 ans")*IF(Data_Clean!O2:O1000="",0,Data_Clean!O2:O1000))/SUMPRODUCT(((Indicateurs!$B$4="Tous")+(Data_Clean!C2:C1000=Indicateurs!$B$4)>0)*((Indicateurs!$B$5="Tous")+(Data_Clean!D2:D1000=Indicateurs!$B$5)>0)*((Indicateurs!$B$6="Tous")+(Data_Clean!G2:G1000=Indicateurs!$B$6)>0)*((Indicateurs!$B$7="")+(Data_Clean!B2:B1000>=Indicateurs!$B$7)>0)*((Indicateurs!$B$8="")+(Data_Clean!B2:B1000<=Indicateurs!$B$8)>0)*(Data_Clean!AG2:AG1000=1)*(Data_Clean!I2:I1000="<18 ans")*(Data_Clean!O2:O1000<>"")),"") | E11: =IFERROR(SUMPRODUCT(((Indicateurs!$B$4="Tous")+(Data_Clean!C2:C1000=Indicateurs!$B$4)>0)*((Indicateurs!$B$5="Tous")+(Data_Clean!D2:D1000=Indicateurs!$B$5)>0)*((Indicateurs!$B$6="Tous")+(Data_Clean!G2:G1000=Indicateurs!$B$6)>0)*((Indicateurs!$B$7="")+(Data_Clean!B2:B1000>=Indicateurs!$B$7)>0)*((Indicateurs!$B$8="")+(Data_Clean!B2:B1000<=Indicateurs!$B$8)>0)*(Data_Clean!AG2:AG1000=1)*(Data_Clean!I2:I1000="<18 ans")*IF(Data_Clean!Q2:Q1000="",0,Data_Clean!Q2:Q1000))/SUMPRODUCT(((Indicateurs!$B$4="Tous")+(Data_Clean!C2:C1000=Indicateurs!$B$4)>0)*((Indicateurs!$B$5="Tous")+(Data_Clean!D2:D1000=Indicateurs!$B$5)>0)*((Indicateurs!$B$6="Tous")+(Data_Clean!G2:G1000=Indicateurs!$B$6)>0)*((Indicateurs!$B$7="")+(Data_Clean!B2:B1000>=Indicateurs!$B$7)>0)*((Indicateurs!$B$8="")+(Data_Clean!B2:B1000<=Indicateurs!$B$8)>0)*(Data_Clean!AG2:AG1000=1)*(Data_Clean!I2:I1000="<18 ans")*(Data_Clean!Q2:Q1000<>"")),"")
